Workbook

Sheet Summary
B2: Apple Inc. (AAPL) | R2: FCF Chart Data
B3: Discounted Cash Flow Valuation | R3: Year | S3: Free Cash Flow
B4: Prepared by: Kaleik Cook | R4: 2023A | S4: ='DCF Model'!B17 -> 99584
B5: Date: June 2026 | R5: 2024A | S5: ='DCF Model'!C17 -> 108807
B6: ($ in millions except per-share data) | R6: 2025A | S6: ='DCF Model'!D17 -> 98767
B7: Key Output | E7: Value | K7: Revenue | R7: 2026E | S7: ='DCF Model'!E17 -> 159939
B8: Current Share Price | D8: #VALUE! | E8: {=_FV(D8,"Price")} -> 315.32 | J8: 2023A | K8: ='DCF Model'!B5 -> 383285 | R8: 2027E | S8: ='DCF Model'!F17 -> 170123.11
B9: Intrinsic Value Per Share | E9: ='DCF Model'!D54 -> 223.22073 | J9: 2024A | K9: ='DCF Model'!C5 -> 391035 | R9: 2028E | S9: ='DCF Model'!G17 -> 178463.48
B10: Implied Upside / Downside | E10: =(E9/E8)-1 -> -0.29208192 | J10: 2025A | K10: ='DCF Model'!D5 -> 416161 | R10: 2029E | S10: ='DCF Model'!H17 -> 186451.02
B11: Enterprise Value | E11: ='DCF Model'!D52 -> 2882397.4 | J11: 2026E | K11: ='DCF Model'!E5 -> 499809.36 | R11: 2030E | S11: ='DCF Model'!I17 -> 192641.68
B12: Equity Value | E12: ='DCF Model'!D53 -> 2944281.4 | J12: 2027E | K12: ='DCF Model'!F5 -> 541793.35
B13: WACC | E13: ='DCF Model'!D47 -> 0.089005658 | J13: 2028E | K13: ='DCF Model'!G5 -> 577551.71
B14: Terminal Growth Rate | E14: ='DCF Model'!B32 -> 0.03 | J14: 2029E | K14: ='DCF Model'!H5 -> 609317.05
B15: Recommendation | E15: Moderately Overvalued | J15: 2030E | K15: 633690
B17: Model Conclusion | C17: Key Assumptions
C18: Assumption | E18: Value
C19: WACC | E19: ='DCF Model'!D47 -> 0.089005658
C20: Terminal Growth | E20: ='DCF Model'!B32 -> 0.03
C21: FY2026 Revenue Growth | E21: ='DCF Model'!B27 -> 0.201
C22: FY2026 Operating Margin | E22: ='DCF Model'!B28 -> 0.324
C23: FY2026 FCF Margin | E23: ='DCF Model'!B30 -> 0.32
G24: Valuation Bridge Date
G25: Component | H25: Value
G26: PV of Forecast FCF | H26: =SUM('DCF Model'!E19:I19) -> 686848.4
G27: PV of Terminal Value | H27: ='DCF Model'!D51 -> 2195549 | R27: Intrinsic Value | T27: Market Value
G28: Enterprise Value | H28: ='DCF Model'!D52 -> 2882397.4 | R28: ='DCF Model'!D54 -> 223.22073 | S28: #VALUE! | T28: {=_FV(S28,"Price")} -> 315.32
G29: Equity Value | H29: ='DCF Model'!D53 -> 2944281.4

Sheet DCF Model
A1: Apple Inc. DCF Valuation
A2: ($ in millions except per-share data)
B3: HISTORICAL FINANCIALS | E3: FORECAST FINANCIALS
B4: 2023A | C4: 2024A | D4: 2025A | E4: 2026E | F4: 2027E | G4: 2028E | H4: 2029E | I4: 2030E
A5: Revenue | B5: 383285 | C5: 391035 | D5: 416161 | E5: =D5*(1+B27) -> 499809.36 | F5: =E5*(1+C27) -> 541793.35 | G5: =F5*(1+D27) -> 577551.71 | H5: =G5*(1+E27) -> 609317.05 | I5: =H5*(1+F27) -> 633689.73
A6: Revenue Growth % | B6: =-2.8% -> -0.028 | C6: =(C5-B5)/B5 -> 0.020219941 | D6: =((D5-C5)/C5) -> 0.064255118
A7: Gross Profit | B7: 169148 | C7: 180683 | D7: 195201
A8: Gross Margin % | B8: =B7/B5 -> 0.4413113 | C8: =C7/C5 -> 0.4620635 | D8: =D7/D5 -> 0.46905164
A9: Operating Income | B9: 114301 | C9: 123216 | D9: 133050 | E9: =E5*B28 -> 161938.23 | F9: =F5*C28 -> 177166.42 | G9: =G5*D28 -> 185971.65 | H9: =H5*E28 -> 194981.46 | I9: =I5*F28 -> 203414.4
A10: Taxes | E10: =E9*B29 -> 25910.117 | F10: =F9*C29 -> 28346.628 | G10: =G9*D29 -> 29755.464 | H10: =H9*E29 -> 31197.033 | I10: =I9*F29 -> 32546.305
A11: NOPAT | E11: =E9-E10 -> 136028.12 | F11: =F9-F10 -> 148819.8 | G11: =G9-G10 -> 156216.19 | H11: =H9-H10 -> 163784.42 | I11: =I9-I10 -> 170868.1
A12: Operating Margin % | B12: =B9/B5 -> 0.29821412 | C12: =C9/C5 -> 0.31510223 | D12: =D9/D5 -> 0.319708
A13: Net Income | B13: 96995 | C13: 93736 | D13: 112010
A14: Net Margin % | B14: =B13/B5 -> 0.25306234 | C14: =C13/C5 -> 0.23971256 | D14: =D13/D5 -> 0.26915064
A15: Operating Cash Flow | B15: 110543 | C15: 118254 | D15: 111482
A16: Capital Expenditures | B16: 10959 | C16: 9447 | D16: 12715
A17: Free Cash Flow | B17: =B15-B16 -> 99584 | C17: =C15-C16 -> 108807 | D17: =D15-D16 -> 98767 | E17: =E5*B30 -> 159939 | F17: =F5*C30 -> 170123.11 | G17: =G5*D30 -> 178463.48 | H17: =H5*E30 -> 186451.02 | I17: =I5*F30 -> 192641.68
A18: Discount Factor | E18: =1/(1+D47)^1 -> 0.91826887 | F18: =1/(1+D47)^2 -> 0.84321773 | G18: =1/(1+D47)^3 -> 0.77430059 | H18: =1/(1+D47)^4 -> 0.71101613 | I18: =1/(1+D47)^5 -> 0.65290398
A19: PV of FCF | E19: =E17*E18 -> 146867 | F19: =F17*F18 -> 143450.82 | G19: =G17*G18 -> 138184.38 | H19: =H17*H18 -> 132569.68 | I19: =I17*I18 -> 125776.52
A20: FCF Margin % | B20: =B17/B5 -> 0.25981711 | C20: =C17/C5 -> 0.27825386 | D20: =D17/D5 -> 0.23732882
A21: Cash & Marketable Securities | B21: =29965+132134 -> 162099 | C21: =29943+35228+91479 -> 156650 | D21: =35934+18763+77723 -> 132420 | E21: 146595
A22: Total Debt | B22: 111088 | C22: 106629 | D22: 98657 | E22: 84711
A23: Shares Outstanding | B23: 15812.547 | C23: 15408.095 | D23: 15004.697 | E23: 13190
B25: FORECAST ASSUMPTIONS
B26: 2026E | C26: 2027E | D26: 2028E | E26: 2029E | F26: 2030E
A27: Revenue Growth % | B27: 0.201 | C27: 0.084 | D27: 0.066 | E27: 0.055 | F27: 0.04
A28: Operating Margin % | B28: 0.324 | C28: 0.327 | D28: 0.322 | E28: 0.32 | F28: 0.321
A29: Tax Rate % | B29: 0.16 | C29: 0.16 | D29: 0.16 | E29: 0.16 | F29: 0.16
A30: FCF Margin % | B30: 0.32 | C30: 0.314 | D30: 0.309 | E30: 0.306 | F30: 0.304
A31: WACC | B31: =D47 -> 0.089005658 | C31: =D47 -> 0.089005658 | D31: =D47 -> 0.089005658 | E31: =D47 -> 0.089005658 | F31: =D47 -> 0.089005658
A32: Terminal Growth Rate | B32: 0.03 | C32: 0.03 | D32: 0.03 | E32: 0.03 | F32: 0.03
B34: WACC BUILD
B35: Input | D35: Value
B36: Risk-Free Rate | C36: #VALUE! | D36: {=_FV(C36,"Yield last month",TRUE)} -> 0.04465
B37: Beta | C37: #VALUE! | D37: {=_FV(C37,"Beta")} -> 1.0932
B38: Equity Risk Premium | D38: 0.0423
B39: Cost of Equity | D39: =D36+(D37*D38) -> 0.09089236
B40: Cost of Debt | D40: =1510/((98657+84710)/2) -> 0.016469703
B41: Tax Rate | D41: 0.16
B42: Market Value of Equity | D42: =298.01*E23 -> 3930751.9
...

Sheet Sensitivity Analysis
C2: Sensitivity Analysis Table
C3: TGR ↓ vs. WACC →
B4: ='DCF Model'!D54 -> 223.22073 | C4: 0.08 | D4: 0.085 | E4: 0.09 | F4: 0.095
B5: 0.02 | C5: 203.84631 | D5: 188.33266 | E5: 175.03762 | F5: 163.51741
B6: 0.0225 | C6: 210.83112 | D6: 194.15578 | E6: 179.95304 | F6: 167.71126
B7: 0.025 | C7: 218.45091 | D7: 200.46417 | E7: 185.24657 | F7: 172.20467
B8: 0.0275 | C8: 226.79639 | D8: 207.32111 | E8: 190.96358 | F8: 177.03093
B9: 0.03 | C9: 235.97642 | D9: 214.80141 | E9: 197.15701 | F9: 182.22843

Sheet Investment Thesis

Sheet Sources
A1: Source | B1: Use
A2: AAPL 10-K | B2: Historical financials, cash, debt, shares
A3: AAPL Q1 10-Q | B3: Year-to-date revenue, operating income, free cash flow
A4: AAPL Q2 10-Q | B4: Year-to-date revenue, operating income, free cash flow
A5: Yahoo Finance | B5: Beta and current share price
A6: TreasuryDirect | B6: 10-Year Treasury yield
A7: Damodaran Online | B7: Equity Risk Premium

Sheet Analyst Disclaimer

Sheet PowerBI_Data
A1: Year | B1: Period Type | C1: Revenue | D1: Operating Income | E1: Free Cash Flow
A2: 2023 | B2: Historical | C2: ='DCF Model'!$B$5 -> 383285 | D2: ='DCF Model'!$B$9 -> 114301 | E2: ='DCF Model'!$B$17 -> 99584
A3: 2024 | B3: Historical | C3: ='DCF Model'!$C$5 -> 391035 | D3: ='DCF Model'!$C$9 -> 123216 | E3: ='DCF Model'!$C$17 -> 108807
A4: 2025 | B4: Historical | C4: ='DCF Model'!$D$5 -> 416161 | D4: ='DCF Model'!$D$9 -> 133050 | E4: ='DCF Model'!$D$17 -> 98767
A5: 2026 | B5: Forecast | C5: ='DCF Model'!$E$5 -> 499809.36 | D5: ='DCF Model'!$E$9 -> 161938.23 | E5: ='DCF Model'!$E$17 -> 159939
A6: 2027 | B6: Forecast | C6: ='DCF Model'!$F$5 -> 541793.35 | D6: ='DCF Model'!$F$9 -> 177166.42 | E6: ='DCF Model'!$F$17 -> 170123.11
A7: 2028 | B7: Forecast | C7: ='DCF Model'!$G$5 -> 577551.71 | D7: ='DCF Model'!$G$9 -> 185971.65 | E7: ='DCF Model'!$G$17 -> 178463.48
A8: 2029 | B8: Forecast | C8: ='DCF Model'!$H$5 -> 609317.05 | D8: ='DCF Model'!$H$9 -> 194981.46 | E8: ='DCF Model'!$H$17 -> 186451.02
A9: 2030 | B9: Forecast | C9: ='DCF Model'!$I$5 -> 633689.73 | D9: ='DCF Model'!$I$9 -> 203414.4 | E9: ='DCF Model'!$I$17 -> 192641.68

Sheet PowerBI_GlobalAssumptions
A1: Assumption | B1: Value | C1: Unit | D1: Description
A2: Risk-Free Rate | B2: ='DCF Model'!D36 -> 0.04465 | C2: Percent | D2: Yield on the 10-year U.S. Treasury used as the baseline return for calculating the cost of equity.
A3: Beta | B3: ='DCF Model'!D37 -> 1.0932 | C3: Multiple | D3: Measures Apple's stock volatility relative to the overall market and is used to estimate investment risk.
A4: Equity Risk Premium | B4: ='DCF Model'!D38 -> 0.0423 | C4: Percent | D4: Additional return investors expect for investing in equities instead of risk-free securities.
A5: Tax Rate | B5: ='DCF Model'!D41 -> 0.16 | C5: Percent | D5: Effective corporate tax rate applied throughout the valuation to estimate after-tax cash flows.
A6: Terminal Growth Rate | B6: ='DCF Model'!B32 -> 0.03 | C6: Percent | D6: Long-term annual growth rate assumed after the explicit forecast period ends.
A7: Cost of Equity | B7: ='DCF Model'!D39 -> 0.09089236 | C7: Percent | D7: Expected return required by equity investors based on the Capital Asset Pricing Model (CAPM).
A8: Cost of Debt | B8: ='DCF Model'!D40 -> 0.016469703 | C8: Percent | D8: Effective interest rate Apple is expected to pay on its outstanding debt, adjusted for taxes in the WACC calculation.
A9: Equity Weight | B9: ='DCF Model'!D45 -> 0.97551576 | C9: Percent | D9: Percentage of the company's capital structure financed through equity.
A10: Debt Weight | B10: ='DCF Model'!D46 -> 0.024484236 | C10: Percent | D10: Percentage of the company's capital structure financed through debt.

Sheet PowerBI_ForecastAssumptions
A1: Year | B1: Revenue Growth | C1: Operating Margin | D1: FCF Margin
A2: 2026 | B2: ='DCF Model'!B27 -> 0.201 | C2: ='DCF Model'!B28 -> 0.324 | D2: ='DCF Model'!B30 -> 0.32
A3: 2027 | B3: ='DCF Model'!C27 -> 0.084 | C3: ='DCF Model'!C28 -> 0.327 | D3: ='DCF Model'!C30 -> 0.314
A4: 2028 | B4: ='DCF Model'!D27 -> 0.066 | C4: ='DCF Model'!D28 -> 0.322 | D4: ='DCF Model'!D30 -> 0.309
A5: 2029 | B5: ='DCF Model'!E27 -> 0.055 | C5: ='DCF Model'!E28 -> 0.32 | D5: ='DCF Model'!E30 -> 0.306
A6: 2030 | B6: ='DCF Model'!F27 -> 0.04 | C6: ='DCF Model'!F28 -> 0.321 | D6: ='DCF Model'!F30 -> 0.304

Sheet PowerBI_Valuation
A1: Current Share Price | B1: Intrinsic Value | C1: Upside | D1: WACC | E1: Terminal Growth
A2: =Summary!E8 -> 315.32 | B2: =Summary!E9 -> 223.22073 | C2: =Summary!E10 -> -0.29208192 | D2: =Summary!E13 -> 0.089005658 | E2: =Summary!E14 -> 0.03

Sheet PowerBI_Summary
A1: Metric | B1: Value
A2: Enterprise Value | B2: ='DCF Model'!D52 -> 2882397.4
A3: Equity Value | B3: ='DCF Model'!D53 -> 2944281.4
A4: Intrinsic Value / Share | B4: ='DCF Model'!D54 -> 223.22073
A5: Current Market Price | B5: =Summary!E8 -> 315.32
A6: Upside / Downside | B6: =Summary!E10 -> -0.29208192

Sheet PowerBI_ValuationBridge
A1: Step | B1: Value
A2: Enterprise Value | B2: ='DCF Model'!D52 -> 2882397.4
A3: Cash | B3: ='DCF Model'!E21 -> 146595
A4: Debt | B4: ='DCF Model'!E22 -> 84711
A5: Equity Value | B5: ='DCF Model'!D53 -> 2944281.4
A6: Intrinsic Value | B6: ='DCF Model'!D54 -> 223.22073
